<?xml version ="1.0"?>

<!-- robot = main tag under which robot is defined-->
<!-- since the system doesnt know what is xacro  we use xmlns:xacro= "http://www.ros.org/wiki/xacro"-->


<robot xmlns:xacro= "http://www.ros.org/wiki/xacro" name ="bumperbot">
    
    <!--we are not linking anything as it is the parent link-->
    <link name="base_footprint"/>

    <!--first link to parent-->
    <link name="base_link">
    <!--start with how it looks-->
        <visual>
    <!--give it the location w.r.t origin-->
            <origin rpy="0 0 0" xyz="0 0 0"/>
            <geometry>
                <!--extracting the mesh from file-->
                <mesh filename="package://bumperbot_description/meshes/base_link.STL" scale="1.0"/>
            </geometry>
        </visual>
    </link>


<!-- creating joints between base_footprint and base_link-->
    <joint name="base_joint" type="fixed">
        <parent link ="base_footprint"/>
        <child link="base_link"/>
        <!--here origin is relative position of child wrt parent. It is 33cm, check diagram-->
        <origin rpy="0.0 0.0 0.0" xyz="0.0 0.0 0.033" />
    </joint>    


    <link name="wheel_right_link">
        <visual>
            <origin rpy="1.57 0 0" xyz = "0 0 0"/>
            <geometry>
                <mesh filename="package://bumperbot_description/meshes/wheel_right_link.STL" scale="1.0"/>
            </geometry>  
        </visual>   
    </link>


    <joint name="wheel_right_joint" type="continuous">
        <parent link ="base_link"/>
        <child link="wheel_right_link"/>
        <axis xyz="0.0 1.0 0.0"/>
        <origin rpy="0.0 0.0 0.0" xyz="0.0 -0.07 0" />
    </joint>

    <link name="wheel_left_link">
        <visual>
            <origin rpy="-1.57 0 0" xyz = "0 0 0"/>
            <geometry>
                <mesh filename="package://bumperbot_description/meshes/wheel_left_link.STL" scale="1.0"/>
            </geometry>  
        </visual>   
    </link>


    <joint name="wheel_left_joint" type="continuous">
        <parent link ="base_link"/>
        <child link="wheel_left_link"/>
        <axis xyz="0.0 1.0 0.0"/>
        <origin rpy="0.0 0.0 0.0" xyz="0.0 0.07 0" />
    </joint>


    <link name="caster_front_link">
        <visual>
            <origin rpy="0 0 0" xyz = "0 0 0"/>
            <geometry>
                <mesh filename="package://bumperbot_description/meshes/caster_front_link.STL" scale="1.0"/>
            </geometry>  
        </visual>   
    </link>


    <joint name="caster_front_joint" type="fixed">
        <parent link ="base_link"/>
        <child link="caster_front_link"/>
        <origin rpy="0.0 0.0 0.0" xyz="0.04755 0 -0.0275" />
    </joint>

    <link name="caster_rear_link">
        <visual>
            <origin rpy="0 0 0" xyz = "0 0 0"/>
            <geometry>
                <mesh filename="package://bumperbot_description/meshes/caster_rear_link.STL" scale="1.0"/>
            </geometry>  
        </visual>   
    </link>


    <joint name="caster_rear_joint" type="fixed">
        <parent link ="base_link"/>
        <child link="caster_rear_link"/>
        <origin rpy="0.0 0.0 0.0" xyz="-0.04755 0 -0.0275" />
    </joint>


</robot>